{"timestamp": "2025-10-04 05:51:23,275", "level": "ERROR", "logger": "mbti_travel_planner.error", "message": {"operation": "search_restaurants_by_district", "error_type": "ConnectError", "error_message": "[Errno 11001] getaddrinfo failed", "timestamp": "2025-10-03T20:51:23.270860", "context": {"request_id": "req_1759524682993_2027401633792", "method": "POST", "url": "https://agentcore_gateway_mcp_tools-UspJsMG7Fi.bedrock-agentcore.us-east-1.amazonaws.com/api/v1/restaurants/search/district", "duration": 0.2778012752532959, "timeout": 60}, "stack_trace": "Traceback (most recent call last):\n  File \"C:\\MBTI_Travel_Assistant\\mbti-travel-planner-agent\\.venv\\Lib\\site-packages\\httpx\\_transports\\default.py\", line 101, in map_httpcore_exceptions\n    yield\n  File \"C:\\MBTI_Travel_Assistant\\mbti-travel-planner-agent\\.venv\\Lib\\site-packages\\httpx\\_transports\\default.py\", line 394, in handle_async_request\n    resp = await self._pool.handle_async_request(req)\n           ^^^^^^^^^^^^^^^^^^^^^^^^^^^^^^^^^^^^^^^^^^\n  File \"C:\\MBTI_Travel_Assistant\\mbti-travel-planner-agent\\.venv\\Lib\\site-packages\\httpcore\\_async\\connection_pool.py\", line 256, in handle_async_request\n    raise exc from None\n  File \"C:\\MBTI_Travel_Assistant\\mbti-travel-planner-agent\\.venv\\Lib\\site-packages\\httpcore\\_async\\connection_pool.py\", line 236, in handle_async_request\n    response = await connection.handle_async_request(\n               ^^^^^^^^^^^^^^^^^^^^^^^^^^^^^^^^^^^^^^\n  File \"C:\\MBTI_Travel_Assistant\\mbti-travel-planner-agent\\.venv\\Lib\\site-packages\\httpcore\\_async\\connection.py\", line 101, in handle_async_request\n    raise exc\n  File \"C:\\MBTI_Travel_Assistant\\mbti-travel-planner-agent\\.venv\\Lib\\site-packages\\httpcore\\_async\\connection.py\", line 78, in handle_async_request\n    stream = await self._connect(request)\n             ^^^^^^^^^^^^^^^^^^^^^^^^^^^^\n  File \"C:\\MBTI_Travel_Assistant\\mbti-travel-planner-agent\\.venv\\Lib\\site-packages\\httpcore\\_async\\connection.py\", line 124, in _connect\n    stream = await self._network_backend.connect_tcp(**kwargs)\n             ^^^^^^^^^^^^^^^^^^^^^^^^^^^^^^^^^^^^^^^^^^^^^^^^^\n  File \"C:\\MBTI_Travel_Assistant\\mbti-travel-planner-agent\\.venv\\Lib\\site-packages\\httpcore\\_backends\\auto.py\", line 31, in connect_tcp\n    return await self._backend.connect_tcp(\n           ^^^^^^^^^^^^^^^^^^^^^^^^^^^^^^^^\n  File \"C:\\MBTI_Travel_Assistant\\mbti-travel-planner-agent\\.venv\\Lib\\site-packages\\httpcore\\_backends\\anyio.py\", line 113, in connect_tcp\n    with map_exceptions(exc_map):\n  File \"C:\\Python312\\Lib\\contextlib.py\", line 158, in __exit__\n    self.gen.throw(value)\n  File \"C:\\MBTI_Travel_Assistant\\mbti-travel-planner-agent\\.venv\\Lib\\site-packages\\httpcore\\_exceptions.py\", line 14, in map_exceptions\n    raise to_exc(exc) from exc\nhttpcore.ConnectError: [Errno 11001] getaddrinfo failed\n\nThe above exception was the direct cause of the following exception:\n\nTraceback (most recent call last):\n  File \"C:\\MBTI_Travel_Assistant\\mbti-travel-planner-agent\\services\\gateway_http_client.py\", line 337, in _make_request\n    response = await client.post(url, headers=headers, json=data)\n               ^^^^^^^^^^^^^^^^^^^^^^^^^^^^^^^^^^^^^^^^^^^^^^^^^^\n  File \"C:\\MBTI_Travel_Assistant\\mbti-travel-planner-agent\\.venv\\Lib\\site-packages\\httpx\\_client.py\", line 1859, in post\n    return await self.request(\n           ^^^^^^^^^^^^^^^^^^^\n  File \"C:\\MBTI_Travel_Assistant\\mbti-travel-planner-agent\\.venv\\Lib\\site-packages\\httpx\\_client.py\", line 1540, in request\n    return await self.send(request, auth=auth, follow_redirects=follow_redirects)\n           ^^^^^^^^^^^^^^^^^^^^^^^^^^^^^^^^^^^^^^^^^^^^^^^^^^^^^^^^^^^^^^^^^^^^^^\n  File \"C:\\MBTI_Travel_Assistant\\mbti-travel-planner-agent\\.venv\\Lib\\site-packages\\httpx\\_client.py\", line 1629, in send\n    response = await self._send_handling_auth(\n               ^^^^^^^^^^^^^^^^^^^^^^^^^^^^^^^\n  File \"C:\\MBTI_Travel_Assistant\\mbti-travel-planner-agent\\.venv\\Lib\\site-packages\\httpx\\_client.py\", line 1657, in _send_handling_auth\n    response = await self._send_handling_redirects(\n               ^^^^^^^^^^^^^^^^^^^^^^^^^^^^^^^^^^^^\n  File \"C:\\MBTI_Travel_Assistant\\mbti-travel-planner-agent\\.venv\\Lib\\site-packages\\httpx\\_client.py\", line 1694, in _send_handling_redirects\n    response = await self._send_single_request(request)\n               ^^^^^^^^^^^^^^^^^^^^^^^^^^^^^^^^^^^^^^^^\n  File \"C:\\MBTI_Travel_Assistant\\mbti-travel-planner-agent\\.venv\\Lib\\site-packages\\httpx\\_client.py\", line 1730, in _send_single_request\n    response = await transport.handle_async_request(request)\n               ^^^^^^^^^^^^^^^^^^^^^^^^^^^^^^^^^^^^^^^^^^^^^\n  File \"C:\\MBTI_Travel_Assistant\\mbti-travel-planner-agent\\.venv\\Lib\\site-packages\\httpx\\_transports\\default.py\", line 393, in handle_async_request\n    with map_httpcore_exceptions():\n  File \"C:\\Python312\\Lib\\contextlib.py\", line 158, in __exit__\n    self.gen.throw(value)\n  File \"C:\\MBTI_Travel_Assistant\\mbti-travel-planner-agent\\.venv\\Lib\\site-packages\\httpx\\_transports\\default.py\", line 118, in map_httpcore_exceptions\n    raise mapped_exc(message) from exc\nhttpx.ConnectError: [Errno 11001] getaddrinfo failed\n"}}
{"timestamp": "2025-10-04 05:51:23,280", "level": "ERROR", "logger": "mbti_travel_planner.error", "message": {"operation": "search_restaurants_by_district", "error_type": "ConnectError", "error_message": "[Errno 11001] getaddrinfo failed", "timestamp": "2025-10-03T20:51:23.279861", "context": {"request_id": "req_1759524682724_2027401633792", "method": "POST", "url": "https://agentcore_gateway_mcp_tools-UspJsMG7Fi.bedrock-agentcore.us-east-1.amazonaws.com/api/v1/restaurants/search/district", "duration": 0.5544772148132324, "timeout": 60}, "stack_trace": "Traceback (most recent call last):\n  File \"C:\\MBTI_Travel_Assistant\\mbti-travel-planner-agent\\.venv\\Lib\\site-packages\\httpx\\_transports\\default.py\", line 101, in map_httpcore_exceptions\n    yield\n  File \"C:\\MBTI_Travel_Assistant\\mbti-travel-planner-agent\\.venv\\Lib\\site-packages\\httpx\\_transports\\default.py\", line 394, in handle_async_request\n    resp = await self._pool.handle_async_request(req)\n           ^^^^^^^^^^^^^^^^^^^^^^^^^^^^^^^^^^^^^^^^^^\n  File \"C:\\MBTI_Travel_Assistant\\mbti-travel-planner-agent\\.venv\\Lib\\site-packages\\httpcore\\_async\\connection_pool.py\", line 256, in handle_async_request\n    raise exc from None\n  File \"C:\\MBTI_Travel_Assistant\\mbti-travel-planner-agent\\.venv\\Lib\\site-packages\\httpcore\\_async\\connection_pool.py\", line 236, in handle_async_request\n    response = await connection.handle_async_request(\n               ^^^^^^^^^^^^^^^^^^^^^^^^^^^^^^^^^^^^^^\n  File \"C:\\MBTI_Travel_Assistant\\mbti-travel-planner-agent\\.venv\\Lib\\site-packages\\httpcore\\_async\\connection.py\", line 101, in handle_async_request\n    raise exc\n  File \"C:\\MBTI_Travel_Assistant\\mbti-travel-planner-agent\\.venv\\Lib\\site-packages\\httpcore\\_async\\connection.py\", line 78, in handle_async_request\n    stream = await self._connect(request)\n             ^^^^^^^^^^^^^^^^^^^^^^^^^^^^\n  File \"C:\\MBTI_Travel_Assistant\\mbti-travel-planner-agent\\.venv\\Lib\\site-packages\\httpcore\\_async\\connection.py\", line 124, in _connect\n    stream = await self._network_backend.connect_tcp(**kwargs)\n             ^^^^^^^^^^^^^^^^^^^^^^^^^^^^^^^^^^^^^^^^^^^^^^^^^\n  File \"C:\\MBTI_Travel_Assistant\\mbti-travel-planner-agent\\.venv\\Lib\\site-packages\\httpcore\\_backends\\auto.py\", line 31, in connect_tcp\n    return await self._backend.connect_tcp(\n           ^^^^^^^^^^^^^^^^^^^^^^^^^^^^^^^^\n  File \"C:\\MBTI_Travel_Assistant\\mbti-travel-planner-agent\\.venv\\Lib\\site-packages\\httpcore\\_backends\\anyio.py\", line 113, in connect_tcp\n    with map_exceptions(exc_map):\n  File \"C:\\Python312\\Lib\\contextlib.py\", line 158, in __exit__\n    self.gen.throw(value)\n  File \"C:\\MBTI_Travel_Assistant\\mbti-travel-planner-agent\\.venv\\Lib\\site-packages\\httpcore\\_exceptions.py\", line 14, in map_exceptions\n    raise to_exc(exc) from exc\nhttpcore.ConnectError: [Errno 11001] getaddrinfo failed\n\nThe above exception was the direct cause of the following exception:\n\nTraceback (most recent call last):\n  File \"C:\\MBTI_Travel_Assistant\\mbti-travel-planner-agent\\services\\gateway_http_client.py\", line 337, in _make_request\n    response = await client.post(url, headers=headers, json=data)\n               ^^^^^^^^^^^^^^^^^^^^^^^^^^^^^^^^^^^^^^^^^^^^^^^^^^\n  File \"C:\\MBTI_Travel_Assistant\\mbti-travel-planner-agent\\.venv\\Lib\\site-packages\\httpx\\_client.py\", line 1859, in post\n    return await self.request(\n           ^^^^^^^^^^^^^^^^^^^\n  File \"C:\\MBTI_Travel_Assistant\\mbti-travel-planner-agent\\.venv\\Lib\\site-packages\\httpx\\_client.py\", line 1540, in request\n    return await self.send(request, auth=auth, follow_redirects=follow_redirects)\n           ^^^^^^^^^^^^^^^^^^^^^^^^^^^^^^^^^^^^^^^^^^^^^^^^^^^^^^^^^^^^^^^^^^^^^^\n  File \"C:\\MBTI_Travel_Assistant\\mbti-travel-planner-agent\\.venv\\Lib\\site-packages\\httpx\\_client.py\", line 1629, in send\n    response = await self._send_handling_auth(\n               ^^^^^^^^^^^^^^^^^^^^^^^^^^^^^^^\n  File \"C:\\MBTI_Travel_Assistant\\mbti-travel-planner-agent\\.venv\\Lib\\site-packages\\httpx\\_client.py\", line 1657, in _send_handling_auth\n    response = await self._send_handling_redirects(\n               ^^^^^^^^^^^^^^^^^^^^^^^^^^^^^^^^^^^^\n  File \"C:\\MBTI_Travel_Assistant\\mbti-travel-planner-agent\\.venv\\Lib\\site-packages\\httpx\\_client.py\", line 1694, in _send_handling_redirects\n    response = await self._send_single_request(request)\n               ^^^^^^^^^^^^^^^^^^^^^^^^^^^^^^^^^^^^^^^^\n  File \"C:\\MBTI_Travel_Assistant\\mbti-travel-planner-agent\\.venv\\Lib\\site-packages\\httpx\\_client.py\", line 1730, in _send_single_request\n    response = await transport.handle_async_request(request)\n               ^^^^^^^^^^^^^^^^^^^^^^^^^^^^^^^^^^^^^^^^^^^^^\n  File \"C:\\MBTI_Travel_Assistant\\mbti-travel-planner-agent\\.venv\\Lib\\site-packages\\httpx\\_transports\\default.py\", line 393, in handle_async_request\n    with map_httpcore_exceptions():\n  File \"C:\\Python312\\Lib\\contextlib.py\", line 158, in __exit__\n    self.gen.throw(value)\n  File \"C:\\MBTI_Travel_Assistant\\mbti-travel-planner-agent\\.venv\\Lib\\site-packages\\httpx\\_transports\\default.py\", line 118, in map_httpcore_exceptions\n    raise mapped_exc(message) from exc\nhttpx.ConnectError: [Errno 11001] getaddrinfo failed\n"}}
{"timestamp": "2025-10-04 05:51:23,284", "level": "ERROR", "logger": "mbti_travel_planner.error", "message": {"operation": "search_restaurants_by_district", "error_type": "ConnectError", "error_message": "[Errno 11001] getaddrinfo failed", "timestamp": "2025-10-03T20:51:23.283863", "context": {"request_id": "req_1759524681961_2027401633792", "method": "POST", "url": "https://agentcore_gateway_mcp_tools-UspJsMG7Fi.bedrock-agentcore.us-east-1.amazonaws.com/api/v1/restaurants/search/district", "duration": 1.3216874599456787, "timeout": 60}, "stack_trace": "Traceback (most recent call last):\n  File \"C:\\MBTI_Travel_Assistant\\mbti-travel-planner-agent\\.venv\\Lib\\site-packages\\httpx\\_transports\\default.py\", line 101, in map_httpcore_exceptions\n    yield\n  File \"C:\\MBTI_Travel_Assistant\\mbti-travel-planner-agent\\.venv\\Lib\\site-packages\\httpx\\_transports\\default.py\", line 394, in handle_async_request\n    resp = await self._pool.handle_async_request(req)\n           ^^^^^^^^^^^^^^^^^^^^^^^^^^^^^^^^^^^^^^^^^^\n  File \"C:\\MBTI_Travel_Assistant\\mbti-travel-planner-agent\\.venv\\Lib\\site-packages\\httpcore\\_async\\connection_pool.py\", line 256, in handle_async_request\n    raise exc from None\n  File \"C:\\MBTI_Travel_Assistant\\mbti-travel-planner-agent\\.venv\\Lib\\site-packages\\httpcore\\_async\\connection_pool.py\", line 236, in handle_async_request\n    response = await connection.handle_async_request(\n               ^^^^^^^^^^^^^^^^^^^^^^^^^^^^^^^^^^^^^^\n  File \"C:\\MBTI_Travel_Assistant\\mbti-travel-planner-agent\\.venv\\Lib\\site-packages\\httpcore\\_async\\connection.py\", line 101, in handle_async_request\n    raise exc\n  File \"C:\\MBTI_Travel_Assistant\\mbti-travel-planner-agent\\.venv\\Lib\\site-packages\\httpcore\\_async\\connection.py\", line 78, in handle_async_request\n    stream = await self._connect(request)\n             ^^^^^^^^^^^^^^^^^^^^^^^^^^^^\n  File \"C:\\MBTI_Travel_Assistant\\mbti-travel-planner-agent\\.venv\\Lib\\site-packages\\httpcore\\_async\\connection.py\", line 124, in _connect\n    stream = await self._network_backend.connect_tcp(**kwargs)\n             ^^^^^^^^^^^^^^^^^^^^^^^^^^^^^^^^^^^^^^^^^^^^^^^^^\n  File \"C:\\MBTI_Travel_Assistant\\mbti-travel-planner-agent\\.venv\\Lib\\site-packages\\httpcore\\_backends\\auto.py\", line 31, in connect_tcp\n    return await self._backend.connect_tcp(\n           ^^^^^^^^^^^^^^^^^^^^^^^^^^^^^^^^\n  File \"C:\\MBTI_Travel_Assistant\\mbti-travel-planner-agent\\.venv\\Lib\\site-packages\\httpcore\\_backends\\anyio.py\", line 113, in connect_tcp\n    with map_exceptions(exc_map):\n  File \"C:\\Python312\\Lib\\contextlib.py\", line 158, in __exit__\n    self.gen.throw(value)\n  File \"C:\\MBTI_Travel_Assistant\\mbti-travel-planner-agent\\.venv\\Lib\\site-packages\\httpcore\\_exceptions.py\", line 14, in map_exceptions\n    raise to_exc(exc) from exc\nhttpcore.ConnectError: [Errno 11001] getaddrinfo failed\n\nThe above exception was the direct cause of the following exception:\n\nTraceback (most recent call last):\n  File \"C:\\MBTI_Travel_Assistant\\mbti-travel-planner-agent\\services\\gateway_http_client.py\", line 337, in _make_request\n    response = await client.post(url, headers=headers, json=data)\n               ^^^^^^^^^^^^^^^^^^^^^^^^^^^^^^^^^^^^^^^^^^^^^^^^^^\n  File \"C:\\MBTI_Travel_Assistant\\mbti-travel-planner-agent\\.venv\\Lib\\site-packages\\httpx\\_client.py\", line 1859, in post\n    return await self.request(\n           ^^^^^^^^^^^^^^^^^^^\n  File \"C:\\MBTI_Travel_Assistant\\mbti-travel-planner-agent\\.venv\\Lib\\site-packages\\httpx\\_client.py\", line 1540, in request\n    return await self.send(request, auth=auth, follow_redirects=follow_redirects)\n           ^^^^^^^^^^^^^^^^^^^^^^^^^^^^^^^^^^^^^^^^^^^^^^^^^^^^^^^^^^^^^^^^^^^^^^\n  File \"C:\\MBTI_Travel_Assistant\\mbti-travel-planner-agent\\.venv\\Lib\\site-packages\\httpx\\_client.py\", line 1629, in send\n    response = await self._send_handling_auth(\n               ^^^^^^^^^^^^^^^^^^^^^^^^^^^^^^^\n  File \"C:\\MBTI_Travel_Assistant\\mbti-travel-planner-agent\\.venv\\Lib\\site-packages\\httpx\\_client.py\", line 1657, in _send_handling_auth\n    response = await self._send_handling_redirects(\n               ^^^^^^^^^^^^^^^^^^^^^^^^^^^^^^^^^^^^\n  File \"C:\\MBTI_Travel_Assistant\\mbti-travel-planner-agent\\.venv\\Lib\\site-packages\\httpx\\_client.py\", line 1694, in _send_handling_redirects\n    response = await self._send_single_request(request)\n               ^^^^^^^^^^^^^^^^^^^^^^^^^^^^^^^^^^^^^^^^\n  File \"C:\\MBTI_Travel_Assistant\\mbti-travel-planner-agent\\.venv\\Lib\\site-packages\\httpx\\_client.py\", line 1730, in _send_single_request\n    response = await transport.handle_async_request(request)\n               ^^^^^^^^^^^^^^^^^^^^^^^^^^^^^^^^^^^^^^^^^^^^^\n  File \"C:\\MBTI_Travel_Assistant\\mbti-travel-planner-agent\\.venv\\Lib\\site-packages\\httpx\\_transports\\default.py\", line 393, in handle_async_request\n    with map_httpcore_exceptions():\n  File \"C:\\Python312\\Lib\\contextlib.py\", line 158, in __exit__\n    self.gen.throw(value)\n  File \"C:\\MBTI_Travel_Assistant\\mbti-travel-planner-agent\\.venv\\Lib\\site-packages\\httpx\\_transports\\default.py\", line 118, in map_httpcore_exceptions\n    raise mapped_exc(message) from exc\nhttpx.ConnectError: [Errno 11001] getaddrinfo failed\n"}}
{"timestamp": "2025-10-04 05:51:23,287", "level": "ERROR", "logger": "mbti_travel_planner.error", "message": {"operation": "search_restaurants_combined", "error_type": "ConnectError", "error_message": "[Errno 11001] getaddrinfo failed", "timestamp": "2025-10-03T20:51:23.286862", "context": {"request_id": "req_1759524682419_2027401633792", "method": "POST", "url": "https://agentcore_gateway_mcp_tools-UspJsMG7Fi.bedrock-agentcore.us-east-1.amazonaws.com/api/v1/restaurants/search/combined", "duration": 0.8677983283996582, "timeout": 60}, "stack_trace": "Traceback (most recent call last):\n  File \"C:\\MBTI_Travel_Assistant\\mbti-travel-planner-agent\\.venv\\Lib\\site-packages\\httpx\\_transports\\default.py\", line 101, in map_httpcore_exceptions\n    yield\n  File \"C:\\MBTI_Travel_Assistant\\mbti-travel-planner-agent\\.venv\\Lib\\site-packages\\httpx\\_transports\\default.py\", line 394, in handle_async_request\n    resp = await self._pool.handle_async_request(req)\n           ^^^^^^^^^^^^^^^^^^^^^^^^^^^^^^^^^^^^^^^^^^\n  File \"C:\\MBTI_Travel_Assistant\\mbti-travel-planner-agent\\.venv\\Lib\\site-packages\\httpcore\\_async\\connection_pool.py\", line 256, in handle_async_request\n    raise exc from None\n  File \"C:\\MBTI_Travel_Assistant\\mbti-travel-planner-agent\\.venv\\Lib\\site-packages\\httpcore\\_async\\connection_pool.py\", line 236, in handle_async_request\n    response = await connection.handle_async_request(\n               ^^^^^^^^^^^^^^^^^^^^^^^^^^^^^^^^^^^^^^\n  File \"C:\\MBTI_Travel_Assistant\\mbti-travel-planner-agent\\.venv\\Lib\\site-packages\\httpcore\\_async\\connection.py\", line 101, in handle_async_request\n    raise exc\n  File \"C:\\MBTI_Travel_Assistant\\mbti-travel-planner-agent\\.venv\\Lib\\site-packages\\httpcore\\_async\\connection.py\", line 78, in handle_async_request\n    stream = await self._connect(request)\n             ^^^^^^^^^^^^^^^^^^^^^^^^^^^^\n  File \"C:\\MBTI_Travel_Assistant\\mbti-travel-planner-agent\\.venv\\Lib\\site-packages\\httpcore\\_async\\connection.py\", line 124, in _connect\n    stream = await self._network_backend.connect_tcp(**kwargs)\n             ^^^^^^^^^^^^^^^^^^^^^^^^^^^^^^^^^^^^^^^^^^^^^^^^^\n  File \"C:\\MBTI_Travel_Assistant\\mbti-travel-planner-agent\\.venv\\Lib\\site-packages\\httpcore\\_backends\\auto.py\", line 31, in connect_tcp\n    return await self._backend.connect_tcp(\n           ^^^^^^^^^^^^^^^^^^^^^^^^^^^^^^^^\n  File \"C:\\MBTI_Travel_Assistant\\mbti-travel-planner-agent\\.venv\\Lib\\site-packages\\httpcore\\_backends\\anyio.py\", line 113, in connect_tcp\n    with map_exceptions(exc_map):\n  File \"C:\\Python312\\Lib\\contextlib.py\", line 158, in __exit__\n    self.gen.throw(value)\n  File \"C:\\MBTI_Travel_Assistant\\mbti-travel-planner-agent\\.venv\\Lib\\site-packages\\httpcore\\_exceptions.py\", line 14, in map_exceptions\n    raise to_exc(exc) from exc\nhttpcore.ConnectError: [Errno 11001] getaddrinfo failed\n\nThe above exception was the direct cause of the following exception:\n\nTraceback (most recent call last):\n  File \"C:\\MBTI_Travel_Assistant\\mbti-travel-planner-agent\\services\\gateway_http_client.py\", line 337, in _make_request\n    response = await client.post(url, headers=headers, json=data)\n               ^^^^^^^^^^^^^^^^^^^^^^^^^^^^^^^^^^^^^^^^^^^^^^^^^^\n  File \"C:\\MBTI_Travel_Assistant\\mbti-travel-planner-agent\\.venv\\Lib\\site-packages\\httpx\\_client.py\", line 1859, in post\n    return await self.request(\n           ^^^^^^^^^^^^^^^^^^^\n  File \"C:\\MBTI_Travel_Assistant\\mbti-travel-planner-agent\\.venv\\Lib\\site-packages\\httpx\\_client.py\", line 1540, in request\n    return await self.send(request, auth=auth, follow_redirects=follow_redirects)\n           ^^^^^^^^^^^^^^^^^^^^^^^^^^^^^^^^^^^^^^^^^^^^^^^^^^^^^^^^^^^^^^^^^^^^^^\n  File \"C:\\MBTI_Travel_Assistant\\mbti-travel-planner-agent\\.venv\\Lib\\site-packages\\httpx\\_client.py\", line 1629, in send\n    response = await self._send_handling_auth(\n               ^^^^^^^^^^^^^^^^^^^^^^^^^^^^^^^\n  File \"C:\\MBTI_Travel_Assistant\\mbti-travel-planner-agent\\.venv\\Lib\\site-packages\\httpx\\_client.py\", line 1657, in _send_handling_auth\n    response = await self._send_handling_redirects(\n               ^^^^^^^^^^^^^^^^^^^^^^^^^^^^^^^^^^^^\n  File \"C:\\MBTI_Travel_Assistant\\mbti-travel-planner-agent\\.venv\\Lib\\site-packages\\httpx\\_client.py\", line 1694, in _send_handling_redirects\n    response = await self._send_single_request(request)\n               ^^^^^^^^^^^^^^^^^^^^^^^^^^^^^^^^^^^^^^^^\n  File \"C:\\MBTI_Travel_Assistant\\mbti-travel-planner-agent\\.venv\\Lib\\site-packages\\httpx\\_client.py\", line 1730, in _send_single_request\n    response = await transport.handle_async_request(request)\n               ^^^^^^^^^^^^^^^^^^^^^^^^^^^^^^^^^^^^^^^^^^^^^\n  File \"C:\\MBTI_Travel_Assistant\\mbti-travel-planner-agent\\.venv\\Lib\\site-packages\\httpx\\_transports\\default.py\", line 393, in handle_async_request\n    with map_httpcore_exceptions():\n  File \"C:\\Python312\\Lib\\contextlib.py\", line 158, in __exit__\n    self.gen.throw(value)\n  File \"C:\\MBTI_Travel_Assistant\\mbti-travel-planner-agent\\.venv\\Lib\\site-packages\\httpx\\_transports\\default.py\", line 118, in map_httpcore_exceptions\n    raise mapped_exc(message) from exc\nhttpx.ConnectError: [Errno 11001] getaddrinfo failed\n"}}
{"timestamp": "2025-10-04 05:51:23,566", "level": "ERROR", "logger": "mbti_travel_planner.error", "message": {"operation": "search_restaurants_combined", "error_type": "ConnectError", "error_message": "[Errno 11001] getaddrinfo failed", "timestamp": "2025-10-03T20:51:23.565376", "context": {"request_id": "req_1759524683289_2027401633792", "method": "POST", "url": "https://agentcore_gateway_mcp_tools-UspJsMG7Fi.bedrock-agentcore.us-east-1.amazonaws.com/api/v1/restaurants/search/combined", "duration": 0.27451467514038086, "timeout": 60}, "stack_trace": "Traceback (most recent call last):\n  File \"C:\\MBTI_Travel_Assistant\\mbti-travel-planner-agent\\.venv\\Lib\\site-packages\\httpx\\_transports\\default.py\", line 101, in map_httpcore_exceptions\n    yield\n  File \"C:\\MBTI_Travel_Assistant\\mbti-travel-planner-agent\\.venv\\Lib\\site-packages\\httpx\\_transports\\default.py\", line 394, in handle_async_request\n    resp = await self._pool.handle_async_request(req)\n           ^^^^^^^^^^^^^^^^^^^^^^^^^^^^^^^^^^^^^^^^^^\n  File \"C:\\MBTI_Travel_Assistant\\mbti-travel-planner-agent\\.venv\\Lib\\site-packages\\httpcore\\_async\\connection_pool.py\", line 256, in handle_async_request\n    raise exc from None\n  File \"C:\\MBTI_Travel_Assistant\\mbti-travel-planner-agent\\.venv\\Lib\\site-packages\\httpcore\\_async\\connection_pool.py\", line 236, in handle_async_request\n    response = await connection.handle_async_request(\n               ^^^^^^^^^^^^^^^^^^^^^^^^^^^^^^^^^^^^^^\n  File \"C:\\MBTI_Travel_Assistant\\mbti-travel-planner-agent\\.venv\\Lib\\site-packages\\httpcore\\_async\\connection.py\", line 101, in handle_async_request\n    raise exc\n  File \"C:\\MBTI_Travel_Assistant\\mbti-travel-planner-agent\\.venv\\Lib\\site-packages\\httpcore\\_async\\connection.py\", line 78, in handle_async_request\n    stream = await self._connect(request)\n             ^^^^^^^^^^^^^^^^^^^^^^^^^^^^\n  File \"C:\\MBTI_Travel_Assistant\\mbti-travel-planner-agent\\.venv\\Lib\\site-packages\\httpcore\\_async\\connection.py\", line 124, in _connect\n    stream = await self._network_backend.connect_tcp(**kwargs)\n             ^^^^^^^^^^^^^^^^^^^^^^^^^^^^^^^^^^^^^^^^^^^^^^^^^\n  File \"C:\\MBTI_Travel_Assistant\\mbti-travel-planner-agent\\.venv\\Lib\\site-packages\\httpcore\\_backends\\auto.py\", line 31, in connect_tcp\n    return await self._backend.connect_tcp(\n           ^^^^^^^^^^^^^^^^^^^^^^^^^^^^^^^^\n  File \"C:\\MBTI_Travel_Assistant\\mbti-travel-planner-agent\\.venv\\Lib\\site-packages\\httpcore\\_backends\\anyio.py\", line 113, in connect_tcp\n    with map_exceptions(exc_map):\n  File \"C:\\Python312\\Lib\\contextlib.py\", line 158, in __exit__\n    self.gen.throw(value)\n  File \"C:\\MBTI_Travel_Assistant\\mbti-travel-planner-agent\\.venv\\Lib\\site-packages\\httpcore\\_exceptions.py\", line 14, in map_exceptions\n    raise to_exc(exc) from exc\nhttpcore.ConnectError: [Errno 11001] getaddrinfo failed\n\nThe above exception was the direct cause of the following exception:\n\nTraceback (most recent call last):\n  File \"C:\\MBTI_Travel_Assistant\\mbti-travel-planner-agent\\services\\gateway_http_client.py\", line 337, in _make_request\n    response = await client.post(url, headers=headers, json=data)\n               ^^^^^^^^^^^^^^^^^^^^^^^^^^^^^^^^^^^^^^^^^^^^^^^^^^\n  File \"C:\\MBTI_Travel_Assistant\\mbti-travel-planner-agent\\.venv\\Lib\\site-packages\\httpx\\_client.py\", line 1859, in post\n    return await self.request(\n           ^^^^^^^^^^^^^^^^^^^\n  File \"C:\\MBTI_Travel_Assistant\\mbti-travel-planner-agent\\.venv\\Lib\\site-packages\\httpx\\_client.py\", line 1540, in request\n    return await self.send(request, auth=auth, follow_redirects=follow_redirects)\n           ^^^^^^^^^^^^^^^^^^^^^^^^^^^^^^^^^^^^^^^^^^^^^^^^^^^^^^^^^^^^^^^^^^^^^^\n  File \"C:\\MBTI_Travel_Assistant\\mbti-travel-planner-agent\\.venv\\Lib\\site-packages\\httpx\\_client.py\", line 1629, in send\n    response = await self._send_handling_auth(\n               ^^^^^^^^^^^^^^^^^^^^^^^^^^^^^^^\n  File \"C:\\MBTI_Travel_Assistant\\mbti-travel-planner-agent\\.venv\\Lib\\site-packages\\httpx\\_client.py\", line 1657, in _send_handling_auth\n    response = await self._send_handling_redirects(\n               ^^^^^^^^^^^^^^^^^^^^^^^^^^^^^^^^^^^^\n  File \"C:\\MBTI_Travel_Assistant\\mbti-travel-planner-agent\\.venv\\Lib\\site-packages\\httpx\\_client.py\", line 1694, in _send_handling_redirects\n    response = await self._send_single_request(request)\n               ^^^^^^^^^^^^^^^^^^^^^^^^^^^^^^^^^^^^^^^^\n  File \"C:\\MBTI_Travel_Assistant\\mbti-travel-planner-agent\\.venv\\Lib\\site-packages\\httpx\\_client.py\", line 1730, in _send_single_request\n    response = await transport.handle_async_request(request)\n               ^^^^^^^^^^^^^^^^^^^^^^^^^^^^^^^^^^^^^^^^^^^^^\n  File \"C:\\MBTI_Travel_Assistant\\mbti-travel-planner-agent\\.venv\\Lib\\site-packages\\httpx\\_transports\\default.py\", line 393, in handle_async_request\n    with map_httpcore_exceptions():\n  File \"C:\\Python312\\Lib\\contextlib.py\", line 158, in __exit__\n    self.gen.throw(value)\n  File \"C:\\MBTI_Travel_Assistant\\mbti-travel-planner-agent\\.venv\\Lib\\site-packages\\httpx\\_transports\\default.py\", line 118, in map_httpcore_exceptions\n    raise mapped_exc(message) from exc\nhttpx.ConnectError: [Errno 11001] getaddrinfo failed\n"}}
{"timestamp": "2025-10-04 05:51:24,118", "level": "ERROR", "logger": "mbti_travel_planner.error", "message": {"operation": "search_restaurants_combined", "error_type": "ConnectError", "error_message": "[Errno 11001] getaddrinfo failed", "timestamp": "2025-10-03T20:51:24.117582", "context": {"request_id": "req_1759524683568_2027401633792", "method": "POST", "url": "https://agentcore_gateway_mcp_tools-UspJsMG7Fi.bedrock-agentcore.us-east-1.amazonaws.com/api/v1/restaurants/search/combined", "duration": 0.5477643013000488, "timeout": 60}, "stack_trace": "Traceback (most recent call last):\n  File \"C:\\MBTI_Travel_Assistant\\mbti-travel-planner-agent\\.venv\\Lib\\site-packages\\httpx\\_transports\\default.py\", line 101, in map_httpcore_exceptions\n    yield\n  File \"C:\\MBTI_Travel_Assistant\\mbti-travel-planner-agent\\.venv\\Lib\\site-packages\\httpx\\_transports\\default.py\", line 394, in handle_async_request\n    resp = await self._pool.handle_async_request(req)\n           ^^^^^^^^^^^^^^^^^^^^^^^^^^^^^^^^^^^^^^^^^^\n  File \"C:\\MBTI_Travel_Assistant\\mbti-travel-planner-agent\\.venv\\Lib\\site-packages\\httpcore\\_async\\connection_pool.py\", line 256, in handle_async_request\n    raise exc from None\n  File \"C:\\MBTI_Travel_Assistant\\mbti-travel-planner-agent\\.venv\\Lib\\site-packages\\httpcore\\_async\\connection_pool.py\", line 236, in handle_async_request\n    response = await connection.handle_async_request(\n               ^^^^^^^^^^^^^^^^^^^^^^^^^^^^^^^^^^^^^^\n  File \"C:\\MBTI_Travel_Assistant\\mbti-travel-planner-agent\\.venv\\Lib\\site-packages\\httpcore\\_async\\connection.py\", line 101, in handle_async_request\n    raise exc\n  File \"C:\\MBTI_Travel_Assistant\\mbti-travel-planner-agent\\.venv\\Lib\\site-packages\\httpcore\\_async\\connection.py\", line 78, in handle_async_request\n    stream = await self._connect(request)\n             ^^^^^^^^^^^^^^^^^^^^^^^^^^^^\n  File \"C:\\MBTI_Travel_Assistant\\mbti-travel-planner-agent\\.venv\\Lib\\site-packages\\httpcore\\_async\\connection.py\", line 124, in _connect\n    stream = await self._network_backend.connect_tcp(**kwargs)\n             ^^^^^^^^^^^^^^^^^^^^^^^^^^^^^^^^^^^^^^^^^^^^^^^^^\n  File \"C:\\MBTI_Travel_Assistant\\mbti-travel-planner-agent\\.venv\\Lib\\site-packages\\httpcore\\_backends\\auto.py\", line 31, in connect_tcp\n    return await self._backend.connect_tcp(\n           ^^^^^^^^^^^^^^^^^^^^^^^^^^^^^^^^\n  File \"C:\\MBTI_Travel_Assistant\\mbti-travel-planner-agent\\.venv\\Lib\\site-packages\\httpcore\\_backends\\anyio.py\", line 113, in connect_tcp\n    with map_exceptions(exc_map):\n  File \"C:\\Python312\\Lib\\contextlib.py\", line 158, in __exit__\n    self.gen.throw(value)\n  File \"C:\\MBTI_Travel_Assistant\\mbti-travel-planner-agent\\.venv\\Lib\\site-packages\\httpcore\\_exceptions.py\", line 14, in map_exceptions\n    raise to_exc(exc) from exc\nhttpcore.ConnectError: [Errno 11001] getaddrinfo failed\n\nThe above exception was the direct cause of the following exception:\n\nTraceback (most recent call last):\n  File \"C:\\MBTI_Travel_Assistant\\mbti-travel-planner-agent\\services\\gateway_http_client.py\", line 337, in _make_request\n    response = await client.post(url, headers=headers, json=data)\n               ^^^^^^^^^^^^^^^^^^^^^^^^^^^^^^^^^^^^^^^^^^^^^^^^^^\n  File \"C:\\MBTI_Travel_Assistant\\mbti-travel-planner-agent\\.venv\\Lib\\site-packages\\httpx\\_client.py\", line 1859, in post\n    return await self.request(\n           ^^^^^^^^^^^^^^^^^^^\n  File \"C:\\MBTI_Travel_Assistant\\mbti-travel-planner-agent\\.venv\\Lib\\site-packages\\httpx\\_client.py\", line 1540, in request\n    return await self.send(request, auth=auth, follow_redirects=follow_redirects)\n           ^^^^^^^^^^^^^^^^^^^^^^^^^^^^^^^^^^^^^^^^^^^^^^^^^^^^^^^^^^^^^^^^^^^^^^\n  File \"C:\\MBTI_Travel_Assistant\\mbti-travel-planner-agent\\.venv\\Lib\\site-packages\\httpx\\_client.py\", line 1629, in send\n    response = await self._send_handling_auth(\n               ^^^^^^^^^^^^^^^^^^^^^^^^^^^^^^^\n  File \"C:\\MBTI_Travel_Assistant\\mbti-travel-planner-agent\\.venv\\Lib\\site-packages\\httpx\\_client.py\", line 1657, in _send_handling_auth\n    response = await self._send_handling_redirects(\n               ^^^^^^^^^^^^^^^^^^^^^^^^^^^^^^^^^^^^\n  File \"C:\\MBTI_Travel_Assistant\\mbti-travel-planner-agent\\.venv\\Lib\\site-packages\\httpx\\_client.py\", line 1694, in _send_handling_redirects\n    response = await self._send_single_request(request)\n               ^^^^^^^^^^^^^^^^^^^^^^^^^^^^^^^^^^^^^^^^\n  File \"C:\\MBTI_Travel_Assistant\\mbti-travel-planner-agent\\.venv\\Lib\\site-packages\\httpx\\_client.py\", line 1730, in _send_single_request\n    response = await transport.handle_async_request(request)\n               ^^^^^^^^^^^^^^^^^^^^^^^^^^^^^^^^^^^^^^^^^^^^^\n  File \"C:\\MBTI_Travel_Assistant\\mbti-travel-planner-agent\\.venv\\Lib\\site-packages\\httpx\\_transports\\default.py\", line 393, in handle_async_request\n    with map_httpcore_exceptions():\n  File \"C:\\Python312\\Lib\\contextlib.py\", line 158, in __exit__\n    self.gen.throw(value)\n  File \"C:\\MBTI_Travel_Assistant\\mbti-travel-planner-agent\\.venv\\Lib\\site-packages\\httpx\\_transports\\default.py\", line 118, in map_httpcore_exceptions\n    raise mapped_exc(message) from exc\nhttpx.ConnectError: [Errno 11001] getaddrinfo failed\n"}}
{"timestamp": "2025-10-04 05:51:24,123", "level": "ERROR", "logger": "mbti_travel_planner.error", "message": {"operation": "search_restaurants_by_district", "error_type": "ConnectError", "error_message": "[Errno 11001] getaddrinfo failed", "timestamp": "2025-10-03T20:51:24.121920", "context": {"request_id": "req_1759524683831_2027401633792", "method": "POST", "url": "https://agentcore_gateway_mcp_tools-UspJsMG7Fi.bedrock-agentcore.us-east-1.amazonaws.com/api/v1/restaurants/search/district", "duration": 0.2893102169036865, "timeout": 60}, "stack_trace": "Traceback (most recent call last):\n  File \"C:\\MBTI_Travel_Assistant\\mbti-travel-planner-agent\\.venv\\Lib\\site-packages\\httpx\\_transports\\default.py\", line 101, in map_httpcore_exceptions\n    yield\n  File \"C:\\MBTI_Travel_Assistant\\mbti-travel-planner-agent\\.venv\\Lib\\site-packages\\httpx\\_transports\\default.py\", line 394, in handle_async_request\n    resp = await self._pool.handle_async_request(req)\n           ^^^^^^^^^^^^^^^^^^^^^^^^^^^^^^^^^^^^^^^^^^\n  File \"C:\\MBTI_Travel_Assistant\\mbti-travel-planner-agent\\.venv\\Lib\\site-packages\\httpcore\\_async\\connection_pool.py\", line 256, in handle_async_request\n    raise exc from None\n  File \"C:\\MBTI_Travel_Assistant\\mbti-travel-planner-agent\\.venv\\Lib\\site-packages\\httpcore\\_async\\connection_pool.py\", line 236, in handle_async_request\n    response = await connection.handle_async_request(\n               ^^^^^^^^^^^^^^^^^^^^^^^^^^^^^^^^^^^^^^\n  File \"C:\\MBTI_Travel_Assistant\\mbti-travel-planner-agent\\.venv\\Lib\\site-packages\\httpcore\\_async\\connection.py\", line 101, in handle_async_request\n    raise exc\n  File \"C:\\MBTI_Travel_Assistant\\mbti-travel-planner-agent\\.venv\\Lib\\site-packages\\httpcore\\_async\\connection.py\", line 78, in handle_async_request\n    stream = await self._connect(request)\n             ^^^^^^^^^^^^^^^^^^^^^^^^^^^^\n  File \"C:\\MBTI_Travel_Assistant\\mbti-travel-planner-agent\\.venv\\Lib\\site-packages\\httpcore\\_async\\connection.py\", line 124, in _connect\n    stream = await self._network_backend.connect_tcp(**kwargs)\n             ^^^^^^^^^^^^^^^^^^^^^^^^^^^^^^^^^^^^^^^^^^^^^^^^^\n  File \"C:\\MBTI_Travel_Assistant\\mbti-travel-planner-agent\\.venv\\Lib\\site-packages\\httpcore\\_backends\\auto.py\", line 31, in connect_tcp\n    return await self._backend.connect_tcp(\n           ^^^^^^^^^^^^^^^^^^^^^^^^^^^^^^^^\n  File \"C:\\MBTI_Travel_Assistant\\mbti-travel-planner-agent\\.venv\\Lib\\site-packages\\httpcore\\_backends\\anyio.py\", line 113, in connect_tcp\n    with map_exceptions(exc_map):\n  File \"C:\\Python312\\Lib\\contextlib.py\", line 158, in __exit__\n    self.gen.throw(value)\n  File \"C:\\MBTI_Travel_Assistant\\mbti-travel-planner-agent\\.venv\\Lib\\site-packages\\httpcore\\_exceptions.py\", line 14, in map_exceptions\n    raise to_exc(exc) from exc\nhttpcore.ConnectError: [Errno 11001] getaddrinfo failed\n\nThe above exception was the direct cause of the following exception:\n\nTraceback (most recent call last):\n  File \"C:\\MBTI_Travel_Assistant\\mbti-travel-planner-agent\\services\\gateway_http_client.py\", line 337, in _make_request\n    response = await client.post(url, headers=headers, json=data)\n               ^^^^^^^^^^^^^^^^^^^^^^^^^^^^^^^^^^^^^^^^^^^^^^^^^^\n  File \"C:\\MBTI_Travel_Assistant\\mbti-travel-planner-agent\\.venv\\Lib\\site-packages\\httpx\\_client.py\", line 1859, in post\n    return await self.request(\n           ^^^^^^^^^^^^^^^^^^^\n  File \"C:\\MBTI_Travel_Assistant\\mbti-travel-planner-agent\\.venv\\Lib\\site-packages\\httpx\\_client.py\", line 1540, in request\n    return await self.send(request, auth=auth, follow_redirects=follow_redirects)\n           ^^^^^^^^^^^^^^^^^^^^^^^^^^^^^^^^^^^^^^^^^^^^^^^^^^^^^^^^^^^^^^^^^^^^^^\n  File \"C:\\MBTI_Travel_Assistant\\mbti-travel-planner-agent\\.venv\\Lib\\site-packages\\httpx\\_client.py\", line 1629, in send\n    response = await self._send_handling_auth(\n               ^^^^^^^^^^^^^^^^^^^^^^^^^^^^^^^\n  File \"C:\\MBTI_Travel_Assistant\\mbti-travel-planner-agent\\.venv\\Lib\\site-packages\\httpx\\_client.py\", line 1657, in _send_handling_auth\n    response = await self._send_handling_redirects(\n               ^^^^^^^^^^^^^^^^^^^^^^^^^^^^^^^^^^^^\n  File \"C:\\MBTI_Travel_Assistant\\mbti-travel-planner-agent\\.venv\\Lib\\site-packages\\httpx\\_client.py\", line 1694, in _send_handling_redirects\n    response = await self._send_single_request(request)\n               ^^^^^^^^^^^^^^^^^^^^^^^^^^^^^^^^^^^^^^^^\n  File \"C:\\MBTI_Travel_Assistant\\mbti-travel-planner-agent\\.venv\\Lib\\site-packages\\httpx\\_client.py\", line 1730, in _send_single_request\n    response = await transport.handle_async_request(request)\n               ^^^^^^^^^^^^^^^^^^^^^^^^^^^^^^^^^^^^^^^^^^^^^\n  File \"C:\\MBTI_Travel_Assistant\\mbti-travel-planner-agent\\.venv\\Lib\\site-packages\\httpx\\_transports\\default.py\", line 393, in handle_async_request\n    with map_httpcore_exceptions():\n  File \"C:\\Python312\\Lib\\contextlib.py\", line 158, in __exit__\n    self.gen.throw(value)\n  File \"C:\\MBTI_Travel_Assistant\\mbti-travel-planner-agent\\.venv\\Lib\\site-packages\\httpx\\_transports\\default.py\", line 118, in map_httpcore_exceptions\n    raise mapped_exc(message) from exc\nhttpx.ConnectError: [Errno 11001] getaddrinfo failed\n"}}
{"timestamp": "2025-10-04 05:51:24,913", "level": "ERROR", "logger": "mbti_travel_planner.error", "message": {"operation": "search_restaurants_by_district", "error_type": "ConnectError", "error_message": "[Errno 11001] getaddrinfo failed", "timestamp": "2025-10-03T20:51:24.911302", "context": {"request_id": "req_1759524684628_2027401633792", "method": "POST", "url": "https://agentcore_gateway_mcp_tools-UspJsMG7Fi.bedrock-agentcore.us-east-1.amazonaws.com/api/v1/restaurants/search/district", "duration": 0.28153443336486816, "timeout": 60}, "stack_trace": "Traceback (most recent call last):\n  File \"C:\\MBTI_Travel_Assistant\\mbti-travel-planner-agent\\.venv\\Lib\\site-packages\\httpx\\_transports\\default.py\", line 101, in map_httpcore_exceptions\n    yield\n  File \"C:\\MBTI_Travel_Assistant\\mbti-travel-planner-agent\\.venv\\Lib\\site-packages\\httpx\\_transports\\default.py\", line 394, in handle_async_request\n    resp = await self._pool.handle_async_request(req)\n           ^^^^^^^^^^^^^^^^^^^^^^^^^^^^^^^^^^^^^^^^^^\n  File \"C:\\MBTI_Travel_Assistant\\mbti-travel-planner-agent\\.venv\\Lib\\site-packages\\httpcore\\_async\\connection_pool.py\", line 256, in handle_async_request\n    raise exc from None\n  File \"C:\\MBTI_Travel_Assistant\\mbti-travel-planner-agent\\.venv\\Lib\\site-packages\\httpcore\\_async\\connection_pool.py\", line 236, in handle_async_request\n    response = await connection.handle_async_request(\n               ^^^^^^^^^^^^^^^^^^^^^^^^^^^^^^^^^^^^^^\n  File \"C:\\MBTI_Travel_Assistant\\mbti-travel-planner-agent\\.venv\\Lib\\site-packages\\httpcore\\_async\\connection.py\", line 101, in handle_async_request\n    raise exc\n  File \"C:\\MBTI_Travel_Assistant\\mbti-travel-planner-agent\\.venv\\Lib\\site-packages\\httpcore\\_async\\connection.py\", line 78, in handle_async_request\n    stream = await self._connect(request)\n             ^^^^^^^^^^^^^^^^^^^^^^^^^^^^\n  File \"C:\\MBTI_Travel_Assistant\\mbti-travel-planner-agent\\.venv\\Lib\\site-packages\\httpcore\\_async\\connection.py\", line 124, in _connect\n    stream = await self._network_backend.connect_tcp(**kwargs)\n             ^^^^^^^^^^^^^^^^^^^^^^^^^^^^^^^^^^^^^^^^^^^^^^^^^\n  File \"C:\\MBTI_Travel_Assistant\\mbti-travel-planner-agent\\.venv\\Lib\\site-packages\\httpcore\\_backends\\auto.py\", line 31, in connect_tcp\n    return await self._backend.connect_tcp(\n           ^^^^^^^^^^^^^^^^^^^^^^^^^^^^^^^^\n  File \"C:\\MBTI_Travel_Assistant\\mbti-travel-planner-agent\\.venv\\Lib\\site-packages\\httpcore\\_backends\\anyio.py\", line 113, in connect_tcp\n    with map_exceptions(exc_map):\n  File \"C:\\Python312\\Lib\\contextlib.py\", line 158, in __exit__\n    self.gen.throw(value)\n  File \"C:\\MBTI_Travel_Assistant\\mbti-travel-planner-agent\\.venv\\Lib\\site-packages\\httpcore\\_exceptions.py\", line 14, in map_exceptions\n    raise to_exc(exc) from exc\nhttpcore.ConnectError: [Errno 11001] getaddrinfo failed\n\nThe above exception was the direct cause of the following exception:\n\nTraceback (most recent call last):\n  File \"C:\\MBTI_Travel_Assistant\\mbti-travel-planner-agent\\services\\gateway_http_client.py\", line 337, in _make_request\n    response = await client.post(url, headers=headers, json=data)\n               ^^^^^^^^^^^^^^^^^^^^^^^^^^^^^^^^^^^^^^^^^^^^^^^^^^\n  File \"C:\\MBTI_Travel_Assistant\\mbti-travel-planner-agent\\.venv\\Lib\\site-packages\\httpx\\_client.py\", line 1859, in post\n    return await self.request(\n           ^^^^^^^^^^^^^^^^^^^\n  File \"C:\\MBTI_Travel_Assistant\\mbti-travel-planner-agent\\.venv\\Lib\\site-packages\\httpx\\_client.py\", line 1540, in request\n    return await self.send(request, auth=auth, follow_redirects=follow_redirects)\n           ^^^^^^^^^^^^^^^^^^^^^^^^^^^^^^^^^^^^^^^^^^^^^^^^^^^^^^^^^^^^^^^^^^^^^^\n  File \"C:\\MBTI_Travel_Assistant\\mbti-travel-planner-agent\\.venv\\Lib\\site-packages\\httpx\\_client.py\", line 1629, in send\n    response = await self._send_handling_auth(\n               ^^^^^^^^^^^^^^^^^^^^^^^^^^^^^^^\n  File \"C:\\MBTI_Travel_Assistant\\mbti-travel-planner-agent\\.venv\\Lib\\site-packages\\httpx\\_client.py\", line 1657, in _send_handling_auth\n    response = await self._send_handling_redirects(\n               ^^^^^^^^^^^^^^^^^^^^^^^^^^^^^^^^^^^^\n  File \"C:\\MBTI_Travel_Assistant\\mbti-travel-planner-agent\\.venv\\Lib\\site-packages\\httpx\\_client.py\", line 1694, in _send_handling_redirects\n    response = await self._send_single_request(request)\n               ^^^^^^^^^^^^^^^^^^^^^^^^^^^^^^^^^^^^^^^^\n  File \"C:\\MBTI_Travel_Assistant\\mbti-travel-planner-agent\\.venv\\Lib\\site-packages\\httpx\\_client.py\", line 1730, in _send_single_request\n    response = await transport.handle_async_request(request)\n               ^^^^^^^^^^^^^^^^^^^^^^^^^^^^^^^^^^^^^^^^^^^^^\n  File \"C:\\MBTI_Travel_Assistant\\mbti-travel-planner-agent\\.venv\\Lib\\site-packages\\httpx\\_transports\\default.py\", line 393, in handle_async_request\n    with map_httpcore_exceptions():\n  File \"C:\\Python312\\Lib\\contextlib.py\", line 158, in __exit__\n    self.gen.throw(value)\n  File \"C:\\MBTI_Travel_Assistant\\mbti-travel-planner-agent\\.venv\\Lib\\site-packages\\httpx\\_transports\\default.py\", line 118, in map_httpcore_exceptions\n    raise mapped_exc(message) from exc\nhttpx.ConnectError: [Errno 11001] getaddrinfo failed\n"}}
